[2;31m[2021-06-08 16:53:07 web web.py:log_exception:1793 ERROR][0m Uncaught exception GET /?user=123 (192.168.1.141)
    HTTPServerRequest(protocol='http', host='192.168.1.141:8001', method='GET', uri='/?user=123', version='HTTP/1.1', remote_ip='192.168.1.141')
    Traceback (most recent call last):
      File "D:\Common\Virtual Environment\Envs\Forecast500\lib\site-packages\tornado\web.py", line 1704, in _execute
        result = await result
      File "E:\Projects\Python_Projects\Forecast500\backend\utils\Decorate.py", line 54, in wrapper
        res = await func(self, *args, **kwargs)
      File "E:\Projects\Python_Projects\Forecast500\controllers\HomeController.py", line 33, in get
        user = await self.get_authenticated_user(
    AttributeError: 'HomeHandler' object has no attribute 'get_authenticated_user'
[2;31m[2021-06-08 16:53:07 web web.py:send_error:1219 ERROR][0m Uncaught exception in write_error
    Traceback (most recent call last):
      File "D:\Common\Virtual Environment\Envs\Forecast500\lib\site-packages\tornado\web.py", line 1704, in _execute
        result = await result
      File "E:\Projects\Python_Projects\Forecast500\backend\utils\Decorate.py", line 54, in wrapper
        res = await func(self, *args, **kwargs)
      File "E:\Projects\Python_Projects\Forecast500\controllers\HomeController.py", line 33, in get
        user = await self.get_authenticated_user(
    AttributeError: 'HomeHandler' object has no attribute 'get_authenticated_user'
    
    During handling of the above exception, another exception occurred:
    
    Traceback (most recent call last):
      File "D:\Common\Virtual Environment\Envs\Forecast500\lib\site-packages\tornado\web.py", line 1217, in send_error
        self.write_error(status_code, **kwargs)
      File "E:\Projects\Python_Projects\Forecast500\backend\core\Basehandler.py", line 83, in write_error
        self.write(ReturnJson.EXCEPTION(error_message=exc_instance))
      File "D:\Common\Virtual Environment\Envs\Forecast500\lib\site-packages\tornado\web.py", line 843, in write
        chunk = escape.json_encode(chunk)
      File "D:\Common\Virtual Environment\Envs\Forecast500\lib\site-packages\tornado\escape.py", line 75, in json_encode
        return json.dumps(value).replace("</", "<\\/")
      File "d:\common\python\python373\lib\json\__init__.py", line 231, in dumps
        return _default_encoder.encode(obj)
      File "d:\common\python\python373\lib\json\encoder.py", line 199, in encode
        chunks = self.iterencode(o, _one_shot=True)
      File "d:\common\python\python373\lib\json\encoder.py", line 257, in iterencode
        return _iterencode(o, 0)
      File "d:\common\python\python373\lib\json\encoder.py", line 179, in default
        raise TypeError(f'Object of type {o.__class__.__name__} '
    TypeError: Object of type AttributeError is not JSON serializable
[2;31m[2021-06-08 16:53:07 web web.py:log_request:2243 ERROR][0m 500 GET /?user=123 (192.168.1.141) 6658.33ms
